Workbook

Sheet Revision_History
B1: ARINC FPGA (SYSTEM_TOP) Register Map
B2: No. | C2: Date | D2: Author | E2: Modification Details
B3: 1 | C3: 2026.10.24 | E3: Draft: register map
B4: 2 | C4: 2026.10.26 | E4: ARINC_717: split into sub-cores per Core717 spec Table 24 (Offset Word Address = block-relative; Word = module base + sub-core Base Address + offset)
B5: 3 | C5: 2026.10.26 | E5: Removed SYSCTRL and MISC sheets; Memory_Map and Module_Address_Usage reduced to DUT_ARINC_717
B6: 4 | C6: 2026.10.26 | E6: ARINC_717: reset values of CORE_VERSION/TX_STATUS/RX_STATUS; added access (SLVERR), clear conditions, reserved bits and usage notes from Core717 spec rev1.85

Sheet Memory_Map
B1: 1. ARINC (Zynq-7000, SYSTEM_TOP) PS memory map - PL slaves
B2: Device | C2: Start Address | D2: Size | E2: Address region | F2: Description
B3: M01_AXI_0 (DUT_test_wrapper) | C3: 0x5000_0000 | D3: 128KB | E3: 0x5000_0000 ~ 0x5001_FFFF | F3: DUT_test: axi_clock_converter -> axi_bram_ctrl -> blk_mem_gen (memory, no registers)
B4: DUT_ARINC_717 (Core717 AXI4-Lite) | C4: 0x6000_0000 | D4: 1KB | E4: 0x6000_0000 ~ 0x6000_03FF | F4: ARINC 717 core (Core717): registers + TX/RX data ports in 0x000 ~ 0x14F (base_addr = 0x6000_0000), 0x150 ~ 0x3FF outside the core window (SLVERR) (see Module_Address_Usage, ARINC_717)

Sheet Module_Address_Usage
B1: ="DUT_ARINC_717 (Base address: "&$C$2&") - Core717 AXI4-Lite address decode"
B2: PS Base Address (base_addr) | C2: 0x60000000
B3: Module Name | C3: Word Start | D3: Word End | E3: Size(Byte) | F3: Usage | G3: Byte Start | H3: Byte End | I3: PS Byte Start | J3: PS Byte End | K3: Source
B4: DUT_ARINC_717 | C4: 0x00000 | D4: 0x000FF | E4: =((HEX2DEC(MID(D4,3,5))+1)-HEX2DEC(MID(C4,3,5)))*4 | F4: O | G4: =CONCATENATE("0x",DEC2HEX(HEX2DEC(MID(C4,3,5))*4,6)) | H4: =CONCATENATE("0x",DEC2HEX(HEX2DEC(MID(D4,3,5))*4+3,6)) | I4: =CONCATENATE("0x",LEFT(DEC2HEX(HEX2DEC(MID($C$2,3,8))+HEX2DEC(MID(G4,3,6)),8),4),"_",RIGHT(DEC2HEX(HEX2DEC(MID($C$2,3,8))+HEX2DEC(MID(G4,3,6)),8),4)) | J4: =CONCATENATE("0x",LEFT(DEC2HEX(HEX2DEC(MID($C$2,3,8))+HEX2DEC(MID(H4,3,6)),8),4),"_",RIGHT(DEC2HEX(HEX2DEC(MID($C$2,3,8))+HEX2DEC(MID(H4,3,6)),8),4)) | K4: Core717_ARINC717_AXI_Lite_Spec rev1.85, Section 7 (register address = base_addr + block_base + Off)
B6: Bus access notes (DUT_ARINC_717 / Core717 AXI4-Lite slave):
B7: ="* Core byte offset = PS byte address - "&$C$2&"; AXI AWADDR/ARADDR are 16-bit and decode 0x0000 ~ 0x014F (Core717 spec 7.1)."
B8: * Word address = core byte offset / 4 (32-bit registers). Local address in DUT_ARINC_717 = word address - module base (starts from 0x00).
B9: * Reserved byte address 0x0000 ~ 0x014F: write ignored, read returns 0, response OKAY. 0x0150 ~ 0x03FF (outside core decode): response SLVERR.
B10: * Type (sheet ARINC_717): RW = read/write, RO = read only, WO = write only, X = unused byte lane (reads 0).

Sheet ARINC_717
A1: Offset Word Address | B1: Type | C1: Register Name | D1: Bit[31] | E1: Bit[30] | F1: Bit[29] | G1: Bit[28] | H1: Bit[27] | I1: Bit[26] | J1: Bit[25] | K1: Bit[24] | L1: Field Description | M1: Value Description | N1: ="DUT_ARINC_717 (Base address: "&Module_Address_Usage!$C$2&")"
D2: Bit[23] | E2: Bit[22] | F2: Bit[21] | G2: Bit[20] | H2: Bit[19] | I2: Bit[18] | J2: Bit[17] | K2: Bit[16]
D3: Bit[15] | E3: Bit[14] | F3: Bit[13] | G3: Bit[12] | H3: Bit[11] | I3: Bit[10] | J3: Bit[9] | K3: Bit[8] | N3: Address | P3: Initial Value | Q3: Usage | R3: PS (AXI) Byte Address
D4: Bit[7] | E4: Bit[6] | F4: Bit[5] | G4: Bit[4] | H4: Bit[3] | I4: Bit[2] | J4: Bit[1] | K4: Bit[0] | N4: Word | O4: Byte
D5: ARINC_717 Module (DUT_ARINC_717 / Core717 AXI4-Lite) | L5: ="Module word address : "&Module_Address_Usage!$C$4&" ~ "&Module_Address_Usage!$D$4&" (local 0x00 ~ 0x"&DEC2HEX(HEX2DEC(MID(Module_Address_Usage!$D$4,3,5))-HEX2DEC(MID(Module_Address_Usage!$C$4,3,5)),2)&")"&CHAR(10)&"PS byte address : "&Module_Address_Usage!$I$4&" ~ "&Module_Address_Usage!$J$4
D9: Global Registers | N9: Base Address | O9: 0x00000
A10: 0x00000 | B10: RO | C10: CORE_VERSION | D10: MAJOR[15:8] | L10: MAJOR[15:0]: RTL major version MINOR[15:0]: RTL minor version Major[31:16] = 1, Minor[15:0] = 0 (not tied to the document revision) | M10: Constant 0x0001_0000 (v1.0) Write returns SLVERR | N10: =CONCATENATE("0x",DEC2HEX(HEX2DEC(MID(Module_Address_Usage!$C$4,3,5))+HEX2DEC(MID($O$9,3,5))+HEX2DEC(MID($A10,3,5)),5)) | O10: =CONCATENATE("0x",DEC2HEX(HEX2DEC(MID($N$10,3,5))*4+3,6)) | P10: 0x00 | Q10: O | R10: =CONCATENATE("0x",LEFT(DEC2HEX(HEX2DEC(MID(Module_Address_Usage!$C$2,3,8))+HEX2DEC(MID($N$10,3,5))*4+0,8),4),"_",RIGHT(DEC2HEX(HEX2DEC(MID(Module_Address_Usage!$C$2,3,8))+HEX2DEC(MID($N$10,3,5))*4+0,8),4))
B11: RO | D11: MAJOR[7:0] | O11: =CONCATENATE("0x",DEC2HEX(HEX2DEC(MID($N$10,3,5))*4+2,6)) | P11: 0x01 | Q11: O
B12: RO | D12: MINOR[15:8] | O12: =CONCATENATE("0x",DEC2HEX(HEX2DEC(MID($N$10,3,5))*4+1,6)) | P12: 0x00 | Q12: O
B13: RO | D13: MINOR[7:0] | O13: =CONCATENATE("0x",DEC2HEX(HEX2DEC(MID($N$10,3,5))*4+0,6)) | P13: 0x00 | Q13: O
A14: 0x00001 | B14: X | C14: GLOBAL_CTRL | L14: SOFT_RESET: soft reset, self-clears when done GLOBAL_EN: core enable TX_EN / RX_EN: TX / RX path enable IRQ_ENABLE: aggregated irq output enable INJ_DST: pattern injector destination Bits [31:6] reserved: write 0, read 0 | M14: 0b0: disable / idle (default) 0b1: enable / start INJ_DST 0b0: TX pins, 0b1: RX input Poll SOFT_RESET until 0b0 before config SOFT_RESET: write 1 starts, stays 1 while busy, self-clears when done INJ_DST: written/applied only while INJ_EN = 0; SOFT_RESET does not change it; no effect if INCLUDE_INJECTOR = 0 TX_EN / RX_EN also require GLOBAL_EN | N14: =CONCATENATE("0x",DEC2HEX(HEX2DEC(MID(Module_Address_Usage!$C$4,3,5))+HEX2DEC(MID($O$9,3,5))+HEX2DEC(MID($A14,3,5)),5)) | O14: =CONCATENATE("0x",DEC2HEX(HEX2DEC(MID($N$14,3,5))*4+3,6)) | P14: - | Q14: X | R14: =CONCATENATE("0x",LEFT(DEC2HEX(HEX2DEC(MID(Module_Address_Usage!$C$2,3,8))+HEX2DEC(MID($N$14,3,5))*4+0,8),4),"_",RIGHT(DEC2HEX(HEX2DEC(MID(Module_Address_Usage!$C$2,3,8))+HEX2DEC(MID($N$14,3,5))*4+0,8),4))
B15: X | O15: =CONCATENATE("0x",DEC2HEX(HEX2DEC(MID($N$14,3,5))*4+2,6)) | P15: - | Q15: X
B16: X | O16: =CONCATENATE("0x",DEC2HEX(HEX2DEC(MID($N$14,3,5))*4+1,6)) | P16: - | Q16: X
B17: RW | F17: INJ_DST | G17: IRQ_ENABLE | H17: RX_EN | I17: TX_EN | J17: GLOBAL_EN | K17: SOFT_RESET | O17: =CONCATENATE("0x",DEC2HEX(HEX2DEC(MID($N$14,3,5))*4+0,6)) | P17: 0x00 | Q17: O
A18: 0x00002 | B18: X | C18: GLOBAL_STATUS | L18: CORE_PENDING: IRQ_SOURCE is not 0 CLR_BUSY: SOFT_RESET or FIFO clear in progress Bits [31:2] reserved, read 0 | M18: 0b0: idle 0b1: pending / busy Write returns SLVERR (no effect) CLR_BUSY = 1: data-port access and FIFO_CLEAR write return SLVERR | N18: =CONCATENATE("0x",DEC2HEX(HEX2DEC(MID(Module_Address_Usage!$C$4,3,5))+HEX2DEC(MID($O$9,3,5))+HEX2DEC(MID($A18,3,5)),5)) | O18: =CONCATENATE("0x",DEC2HEX(HEX2DEC(MID($N$18,3,5))*4+3,6)) | P18: - | Q18: X | R18: =CONCATENATE("0x",LEFT(DEC2HEX(HEX2DEC(MID(Module_Address_Usage!$C$2,3,8))+HEX2DEC(MID($N$18,3,5))*4+0,8),4),"_",RIGHT(DEC2HEX(HEX2DEC(MID(Module_Address_Usage!$C$2,3,8))+HEX2DEC(MID($N$18,3,5))*4+0,8),4))
B19: X | O19: =CONCATENATE("0x",DEC2HEX(HEX2DEC(MID($N$18,3,5))*4+2,6)) | P19: - | Q19: X
B20: X | O20: =CONCATENATE("0x",DEC2HEX(HEX2DEC(MID($N$18,3,5))*4+1,6)) | P20: - | Q20: X
B21: RO | J21: CLR_BUSY | K21: CORE_PENDING | O21: =CONCATENATE("0x",DEC2HEX(HEX2DEC(MID($N$18,3,5))*4+0,6)) | P21: - | Q21: O
A22: 0x00003 | B22: X | C22: IRQ_SOURCE | L22: [3:0]: TX_IRQ_STATUS AND TX_IRQ_ENABLE [22:16]: RX_IRQ_STATUS AND RX_IRQ_ENABLE Not gated by GLOBAL_CTRL.IRQ_ENABLE Bit n of RX_IRQ_STATUS is bit 16 + n; other bits reserved, read 0 | M22: 0b0: no request 0b1: source requests irq Clear by W1C on TX/RX_IRQ_STATUS Write returns SLVERR (no effect) | N22: =CONCATENATE("0x",DEC2HEX(HEX2DEC(MID(Module_Address_Usage!$C$4,3,5))+HEX2DEC(MID($O$9,3,5))+HEX2DEC(MID($A22,3,5)),5)) | O22: =CONCATENATE("0x",DEC2HEX(HEX2DEC(MID($N$22,3,5))*4+3,6)) | P22: - | Q22: X | R22: =CONCATENATE("0x",LEFT(DEC2HEX(HEX2DEC(MID(Module_Address_Usage!$C$2,3,8))+HEX2DEC(MID($N$22,3,5))*4+0,8),4),"_",RIGHT(DEC2HEX(HEX2DEC(MID(Module_Address_Usage!$C$2,3,8))+HEX2DEC(MID($N$22,3,5))*4+0,8),4))
B23: RO | E23: RX_BIT_ERR | F23: RX_INSYNC_LOST | G23: RX_MATCH | H23: RX_OVERFLOW | I23: RX_FULL | J23: RX_HALF | K23: RX_EMPTY | O23: =CONCATENATE("0x",DEC2HEX(HEX2DEC(MID($N$22,3,5))*4+2,6)) | P23: - | Q23: O
B24: X | O24: =CONCATENATE("0x",DEC2HEX(HEX2DEC(MID($N$22,3,5))*4+1,6)) | P24: - | Q24: X
B25: RO | H25: TX_UNDERRUN | I25: TX_FULL | J25: TX_LOW | K25: TX_EMPTY | O25: =CONCATENATE("0x",DEC2HEX(HEX2DEC(MID($N$22,3,5))*4+0,6)) | P25: - | Q25: O
A26: 0x00004 ~ 0x00007 | B26: X | C26: Reserved | L26: Reserved | M26: Write ignored, read returns 0x0000_0000 | N26: =CONCATENATE("0x",DEC2HEX(HEX2DEC(MID(Module_Address_Usage!$C$4,3,5))+HEX2DEC(MID($O$9,3,5))+HEX2DEC(MID($A26,3,5)),5))&CHAR(10)&"~ "&CONCATENATE("0x",DEC2HEX(HEX2DEC(MID(Module_Address_Usage!$C$4,3,5))+HEX2DEC(MID($O$9,3,5))+HEX2DEC(MID($A26,13,5)),5)) | O26: =CONCATENATE("0x",DEC2HEX(HEX2DEC(MID(CONCATENATE("0x",DEC2HEX(HEX2DEC(MID(Module_Address_Usage!$C$4,3,5))+HEX2DEC(MID($O$9,3,5))+HEX2DEC(MID($A26,3,5)),5)),3,5))*4+0,6))&CHAR(10)&"~ "&CONCATENATE("0x",DEC2HEX(HEX2DEC(MID(CONCATENATE("0x",DEC2HEX(HEX2DEC(MID(Module_Address_Usage!$C$4,3,5))+HEX2DEC(MID($O$9,3,5))+HEX2DEC(MID($A26,13,5)),5)),3,5))*4+3,6)) | P26: - | Q26: X | R26: =CONCATENATE("0x",LEFT(DEC2HEX(HEX2DEC(MID(Module_Address_Usage!$C$2,3,8))+HEX2DEC(MID(CONCATENATE("0x",DEC2HEX(HEX2DEC(MID(Module_Address_Usage!$C$4,3,5))+HEX2DEC(MID($O$9,3,5))+HEX2DEC(MID($A26,3,5)),5)),3,5))*4+0,8),4),"_",RIGHT(DEC2HEX(HEX2DEC(MID(Module_Address_Usage!$C$2,3,8))+HEX2DEC(MID(CONCATENATE("0x",DEC2HEX(HEX2DEC(MID(Module_Address_Usage!$C$4,3,5))+HEX2DEC(MID($O$9,3,5))+HEX2DEC(MID($A26,3,5)),5)),3,5))*4+0,8),4))&CHAR(10)&"~ "&CONCATENATE("0x",LEFT(DEC2HEX(HEX2DEC(MID(Module_Address_Usage!$C$2,3,8))+HEX2DEC(MID(CONCATENATE("0x",DEC2HEX(HEX2DEC(MID(Module_Address_Usage!$C$4,3,5))+HEX2DEC(MID($O$9,3,5))+HEX2DEC(MID($A26,13,5)),5)),3,5))*4+3,8),4),"_",RIGHT(DEC2HEX(HEX2DEC(MID(Module_Address_Usage!$C$2,3,8))+HEX2DEC(MID(CONCATENATE("0x",DEC2HEX(HEX2DEC(MID(Module_Address_Usage!$C$4,3,5))+HEX2DEC(MID($O$9,3,5))+HEX2DEC(MID($A26,13,5)),5)),3,5))*4+3,8),4))
D27: TX Control / Status | N27: Base Address | O27: 0x00008
A28: 0x00000 | B28: X | C28: TX_CTRL | L28: SYNC_INS_MODE: sync word insertion mode TX_RATE[3:0]: TX word-rate select (spec Table 5) Applied only while tx_active = 0 Bits [7:1] and [31:12] reserved: write 0, read 0 | M28: SYNC_INS_MODE 0b0: software inserts sync SYNC_INS_MODE 0b1: hardware inserts TX_SYNCx TX_RATE 0x8 ~ 0xF: as 0x0 (64 wps) | N28: =CONCATENATE("0x",DEC2HEX(HEX2DEC(MID(Module_Address_Usage!$C$4,3,5))+HEX2DEC(MID($O$27,3,5))+HEX2DEC(MID($A28,3,5)),5)) | O28: =CONCATENATE("0x",DEC2HEX(HEX2DEC(MID($N$28,3,5))*4+3,6)) | P28: - | Q28: X | R28: =CONCATENATE("0x",LEFT(DEC2HEX(HEX2DEC(MID(Module_Address_Usage!$C$2,3,8))+HEX2DEC(MID($N$28,3,5))*4+0,8),4),"_",RIGHT(DEC2HEX(HEX2DEC(MID(Module_Address_Usage!$C$2,3,8))+HEX2DEC(MID($N$28,3,5))*4+0,8),4))
B29: X | O29: =CONCATENATE("0x",DEC2HEX(HEX2DEC(MID($N$28,3,5))*4+2,6)) | P29: - | Q29: X
B30: RW | H30: TX_RATE[3:0] | O30: =CONCATENATE("0x",DEC2HEX(HEX2DEC(MID($N$28,3,5))*4+1,6)) | P30: 0x00 | Q30: O
B31: RW | K31: SYNC_INS_MODE | O31: =CONCATENATE("0x",DEC2HEX(HEX2DEC(MID($N$28,3,5))*4+0,6)) | P31: 0x00 | Q31: O
A32: 0x00001 | B32: X | C32: TX_STATUS | L32: EMPTY: TX FIFO level = 0 HALF: TX FIFO level >= FIFO_DEPTH/2 FULL: TX FIFO level = FIFO_DEPTH | M32: 0b0: false 0b1: true (reset: EMPTY = 1) Write returns SLVERR (no effect) | N32: =CONCATENATE("0x",DEC2HEX(HEX2DEC(MID(Module_Address_Usage!$C$4,3,5))+HEX2DEC(MID($O$27,3,5))+HEX2DEC(MID($A32,3,5)),5)) | O32: =CONCATENATE("0x",DEC2HEX(HEX2DEC(MID($N$32,3,5))*4+3,6)) | P32: - | Q32: X | R32: =CONCATENATE("0x",LEFT(DEC2HEX(HEX2DEC(MID(Module_Address_Usage!$C$2,3,8))+HEX2DEC(MID($N$32,3,5))*4+0,8),4),"_",RIGHT(DEC2HEX(HEX2DEC(MID(Module_Address_Usage!$C$2,3,8))+HEX2DEC(MID($N$32,3,5))*4+0,8),4))
B33: X | O33: =CONCATENATE("0x",DEC2HEX(HEX2DEC(MID($N$32,3,5))*4+2,6)) | P33: - | Q33: X
B34: X | O34: =CONCATENATE("0x",DEC2HEX(HEX2DEC(MID($N$32,3,5))*4+1,6)) | P34: - | Q34: X
B35: RO | I35: FULL | J35: HALF | K35: EMPTY | O35: =CONCATENATE("0x",DEC2HEX(HEX2DEC(MID($N$32,3,5))*4+0,6)) | P35: 0x01 | Q35: O
A36: 0x00002 ~ 0x00003 | B36: X | C36: Reserved | L36: Reserved | M36: Write ignored, read returns 0x0000_0000 | N36: =CONCATENATE("0x",DEC2HEX(HEX2DEC(MID(Module_Address_Usage!$C$4,3,5))+HEX2DEC(MID($O$27,3,5))+HEX2DEC(MID($A36,3,5)),5))&CHAR(10)&"~ "&CONCATENATE("0x",DEC2HEX(HEX2DEC(MID(Module_Address_Usage!$C$4,3,5))+HEX2DEC(MID($O$27,3,5))+HEX2DEC(MID($A36,13,5)),5)) | O36: =CONCATENATE("0x",DEC2HEX(HEX2DEC(MID(CONCATENATE("0x",DEC2HEX(HEX2DEC(MID(Module_Address_Usage!$C$4,3,5))+HEX2DEC(MID($O$27,3,5))+HEX2DEC(MID($A36,3,5)),5)),3,5))*4+0,6))&CHAR(10)&"~ "&CONCATENATE("0x",DEC2HEX(HEX2DEC(MID(CONCATENATE("0x",DEC2HEX(HEX2DEC(MID(Module_Address_Usage!$C$4,3,5))+HEX2DEC(MID($O$27,3,5))+HEX2DEC(MID($A36,13,5)),5)),3,5))*4+3,6)) | P36: - | Q36: X | R36: =CONCATENATE("0x",LEFT(DEC2HEX(HEX2DEC(MID(Module_Address_Usage!$C$2,3,8))+HEX2DEC(MID(CONCATENATE("0x",DEC2HEX(HEX2DEC(MID(Module_Address_Usage!$C$4,3,5))+HEX2DEC(MID($O$27,3,5))+HEX2DEC(MID($A36,3,5)),5)),3,5))*4+0,8),4),"_",RIGHT(DEC2HEX(HEX2DEC(MID(Module_Address_Usage!$C$2,3,8))+HEX2DEC(MID(CONCATENATE("0x",DEC2HEX(HEX2DEC(MID(Module_Address_Usage!$C$4,3,5))+HEX2DEC(MID($O$27,3,5))+HEX2DEC(MID($A36,3,5)),5)),3,5))*4+0,8),4))&CHAR(10)&"~ "&CONCATENATE("0x",LEFT(DEC2HEX(HEX2DEC(MID(Module_Address_Usage!$C$2,3,8))+HEX2DEC(MID(CONCATENATE("0x",DEC2HEX(HEX2DEC(MID(Module_Address_Usage!$C$4,3,5))+HEX2DEC(MID($O$27,3,5))+HEX2DEC(MID($A36,13,5)),5)),3,5))*4+3,8),4),"_",RIGHT(DEC2HEX(HEX2DEC(MID(Module_Address_Usage!$C$2,3,8))+HEX2DEC(MID(CONCATENATE("0x",DEC2HEX(HEX2DEC(MID(Module_Address_Usage!$C$4,3,5))+HEX2DEC(MID($O$27,3,5))+HEX2DEC(MID($A36,13,5)),5)),3,5))*4+3,8),4))
A37: 0x00004 | B37: X | C37: TX_IRQ_ENABLE | L37: Interrupt enable of TX_IRQ_STATUS bits | M37: 0b0: disable 0b1: enable | N37: =CONCATENATE("0x",DEC2HEX(HEX2DEC(MID(Module_Address_Usage!$C$4,3,5))+HEX2DEC(MID($O$27,3,5))+HEX2DEC(MID($A37,3,5)),5)) | O37: =CONCATENATE("0x",DEC2HEX(HEX2DEC(MID($N$37,3,5))*4+3,6)) | P37: - | Q37: X | R37: =CONCATENATE("0x",LEFT(DEC2HEX(HEX2DEC(MID(Module_Address_Usage!$C$2,3,8))+HEX2DEC(MID($N$37,3,5))*4+0,8),4),"_",RIGHT(DEC2HEX(HEX2DEC(MID(Module_Address_Usage!$C$2,3,8))+HEX2DEC(MID($N$37,3,5))*4+0,8),4))
B38: X | O38: =CONCATENATE("0x",DEC2HEX(HEX2DEC(MID($N$37,3,5))*4+2,6)) | P38: - | Q38: X
B39: X | O39: =CONCATENATE("0x",DEC2HEX(HEX2DEC(MID($N$37,3,5))*4+1,6)) | P39: - | Q39: X
B40: RW | H40: EN_UNDERRUN | I40: EN_FULL | J40: EN_LOW | K40: EN_EMPTY | O40: =CONCATENATE("0x",DEC2HEX(HEX2DEC(MID($N$37,3,5))*4+0,6)) | P40: 0x00 | Q40: O
A41: 0x00005 | B41: X | C41: TX_IRQ_STATUS | L41: ST_EMPTY: TX FIFO becomes empty ST_LOW: level falls below FIFO_DEPTH/2 ST_FULL: TX FIFO becomes full ST_UNDERRUN: FIFO empty at a word_tick | M41: Sticky, edge-triggered W1C: write 0b1 to clear Cleared bits are those written with 0b1; bits written with 0b0 are unchanged | N41: =CONCATENATE("0x",DEC2HEX(HEX2DEC(MID(Module_Address_Usage!$C$4,3,5))+HEX2DEC(MID($O$27,3,5))+HEX2DEC(MID($A41,3,5)),5)) | O41: =CONCATENATE("0x",DEC2HEX(HEX2DEC(MID($N$41,3,5))*4+3,6)) | P41: - | Q41: X | R41: =CONCATENATE("0x",LEFT(DEC2HEX(HEX2DEC(MID(Module_Address_Usage!$C$2,3,8))+HEX2DEC(MID($N$41,3,5))*4+0,8),4),"_",RIGHT(DEC2HEX(HEX2DEC(MID(Module_Address_Usage!$C$2,3,8))+HEX2DEC(MID($N$41,3,5))*4+0,8),4))
B42: X | O42: =CONCATENATE("0x",DEC2HEX(HEX2DEC(MID($N$41,3,5))*4+2,6)) | P42: - | Q42: X
B43: X | O43: =CONCATENATE("0x",DEC2HEX(HEX2DEC(MID($N$41,3,5))*4+1,6)) | P43: - | Q43: X
...
