Workbook

Sheet Revision_History
B1: ARINC FPGA (SYSTEM_TOP) Register Map
B2: No. | C2: Date | D2: Author | E2: Modification Details
B3: 1 | C3: 2026.10.24 | E3: Draft: register map
B4: 2
B5: 3

Sheet Memory_Map
B1: 1. ARINC (Zynq-7000, SYSTEM_TOP) PS memory map - PL slaves
B2: Device | C2: Start Address | D2: Size | E2: Address region | F2: Description
B3: axi_lite_PL_0 (M00 of PS7 interconnect) | C3: 0x4000_0000 | D3: 1MB | E3: 0x4000_0000 ~ 0x400F_FFFF | F3: Register CPU bus: axi_lite_PL -> CPUIF_TOP -> SYSCTRL_TOP / MISC_TOP (see Module_Address_Usage)
B4: M01_AXI_0 (DUT_test_wrapper) | C4: 0x5000_0000 | D4: 128KB | E4: 0x5000_0000 ~ 0x5001_FFFF | F4: DUT_test: axi_clock_converter -> axi_bram_ctrl -> blk_mem_gen (memory, no registers)
B5: DUT_ARINC_717 (Core717 AXI4-Lite) | C5: 0x6000_0000 | D5: 1KB | E5: 0x6000_0000 ~ 0x6000_03FF | F5: ARINC 717 core (Core717): registers + TX/RX data ports in 0x000 ~ 0x14F, 0x150 ~ 0x3FF outside the core window (SLVERR) (see Module_Address_Usage, ARINC_717)

Sheet Module_Address_Usage
B1: ="ARINC (Base address: "&$C$2&") - CPUIF_TOP address decode" -> ARINC (Base address: 0x40000000) - CPUIF_TOP address decode
B2: PS Base Address | C2: 0x40000000
B3: Module Name | C3: Word Start | D3: Word End | E3: Size(Byte) | F3: Usage | G3: Byte Start | H3: Byte End | I3: PS Byte Start | J3: PS Byte End | K3: Source
B4: SYSCTRL | C4: 0x00000 | D4: 0x0007F | E4: =((HEX2DEC(MID(D4,3,5))+1)-HEX2DEC(MID(C4,3,5)))*4 -> 512 | F4: O | G4: =CONCATENATE("0x",DEC2HEX(HEX2DEC(MID(C4,3,5))*4,6)) -> 0x000000 | H4: =CONCATENATE("0x",DEC2HEX(HEX2DEC(MID(D4,3,5))*4+3,6)) -> 0x0001FF | I4: =CONCATENATE("0x",LEFT(DEC2HEX(HEX2DEC(MID($C$2,3,8))+HEX2DEC(MID(G4,3,6)),8),4),"_",RIGHT(DEC2HEX(HEX2DEC(MID($C$2,3,8))+HEX2DEC(MID(G4,3,6)),8),4)) -> 0x4000_0000 | J4: =CONCATENATE("0x",LEFT(DEC2HEX(HEX2DEC(MID($C$2,3,8))+HEX2DEC(MID(H4,3,6)),8),4),"_",RIGHT(DEC2HEX(HEX2DEC(MID($C$2,3,8))+HEX2DEC(MID(H4,3,6)),8),4)) -> 0x4000_01FF | K4: SYSCTRL/SYSCTRL_TOP.v, CPUIF_SYSCTRL.v
B5: MISC | C5: 0x00080 | D5: 0x000FF | E5: =((HEX2DEC(MID(D5,3,5))+1)-HEX2DEC(MID(C5,3,5)))*4 -> 512 | F5: O | G5: =CONCATENATE("0x",DEC2HEX(HEX2DEC(MID(C5,3,5))*4,6)) -> 0x000200 | H5: =CONCATENATE("0x",DEC2HEX(HEX2DEC(MID(D5,3,5))*4+3,6)) -> 0x0003FF | I5: =CONCATENATE("0x",LEFT(DEC2HEX(HEX2DEC(MID($C$2,3,8))+HEX2DEC(MID(G5,3,6)),8),4),"_",RIGHT(DEC2HEX(HEX2DEC(MID($C$2,3,8))+HEX2DEC(MID(G5,3,6)),8),4)) -> 0x4000_0200 | J5: =CONCATENATE("0x",LEFT(DEC2HEX(HEX2DEC(MID($C$2,3,8))+HEX2DEC(MID(H5,3,6)),8),4),"_",RIGHT(DEC2HEX(HEX2DEC(MID($C$2,3,8))+HEX2DEC(MID(H5,3,6)),8),4)) -> 0x4000_03FF | K5: MISC/MISC_TOP.v, CPUIF_MISC.v
B6: Reserved | C6: 0x00100 | D6: 0x3FFFF | E6: =((HEX2DEC(MID(D6,3,5))+1)-HEX2DEC(MID(C6,3,5)))*4 -> 1047552 | F6: X | G6: =CONCATENATE("0x",DEC2HEX(HEX2DEC(MID(C6,3,5))*4,6)) -> 0x000400 | H6: =CONCATENATE("0x",DEC2HEX(HEX2DEC(MID(D6,3,5))*4+3,6)) -> 0x0FFFFF | I6: =CONCATENATE("0x",LEFT(DEC2HEX(HEX2DEC(MID($C$2,3,8))+HEX2DEC(MID(G6,3,6)),8),4),"_",RIGHT(DEC2HEX(HEX2DEC(MID($C$2,3,8))+HEX2DEC(MID(G6,3,6)),8),4)) -> 0x4000_0400 | J6: =CONCATENATE("0x",LEFT(DEC2HEX(HEX2DEC(MID($C$2,3,8))+HEX2DEC(MID(H6,3,6)),8),4),"_",RIGHT(DEC2HEX(HEX2DEC(MID($C$2,3,8))+HEX2DEC(MID(H6,3,6)),8),4)) -> 0x400F_FFFF | K6: Write ignored, read returns 0
B8: Bus access notes (axi_lite_PL / CPUIF_TOP):
B9: ="* Word address = PS byte address[21:2] (user_add[19:0]); PS byte address = "&$C$2&" + word address x 4." -> * Word address = PS byte address[21:2] (user_add[19:0]); PS byte address = 0x40000000 + word address x 4.
B10: * 32-bit access only: WSTRB is ignored, response is always OKAY.
B11: * Ack comes C_ACK_DLY (=15) FCLK_CLK0 clocks after the rising edge of rd/wr.
B12: * Local address in each module = word address - module base (starts from 0x00).
B13: * Read of an address outside SYSCTRL/MISC returns 0x0000_0000 (no RDVAL); write is ignored.
B14: * Type: RW = read/write, RO = read only, X = unused byte lane (reads 0).
B15: * Usage: O = bits used in this byte lane, X = byte lane unused.
B17: ="DUT_ARINC_717 (Base address: "&$C$18&") - Core717 AXI4-Lite address decode" -> DUT_ARINC_717 (Base address: 0x60000000) - Core717 AXI4-Lite address decode
B18: PS Base Address | C18: 0x60000000
B19: Module Name | C19: Word Start | D19: Word End | E19: Size(Byte) | F19: Usage | G19: Byte Start | H19: Byte End | I19: PS Byte Start | J19: PS Byte End | K19: Source
B20: DUT_ARINC_717 | C20: 0x00000 | D20: 0x000FF | E20: =((HEX2DEC(MID(D20,3,5))+1)-HEX2DEC(MID(C20,3,5)))*4 -> 1024 | F20: O | G20: =CONCATENATE("0x",DEC2HEX(HEX2DEC(MID(C20,3,5))*4,6)) -> 0x000000 | H20: =CONCATENATE("0x",DEC2HEX(HEX2DEC(MID(D20,3,5))*4+3,6)) -> 0x0003FF | I20: =CONCATENATE("0x",LEFT(DEC2HEX(HEX2DEC(MID($C$18,3,8))+HEX2DEC(MID(G20,3,6)),8),4),"_",RIGHT(DEC2HEX(HEX2DEC(MID($C$18,3,8))+HEX2DEC(MID(G20,3,6)),8),4)) -> 0x6000_0000 | J20: =CONCATENATE("0x",LEFT(DEC2HEX(HEX2DEC(MID($C$18,3,8))+HEX2DEC(MID(H20,3,6)),8),4),"_",RIGHT(DEC2HEX(HEX2DEC(MID($C$18,3,8))+HEX2DEC(MID(H20,3,6)),8),4)) -> 0x6000_03FF | K20: Core717_ARINC717_AXI_Lite_Spec rev1.85, Section 7
B22: Bus access notes (DUT_ARINC_717 / Core717 AXI4-Lite slave):
B23: ="* Core byte offset = PS byte address - "&$C$18&"; AXI AWADDR/ARADDR are 16-bit and decode 0x0000 ~ 0x014F (Core717 spec 7.1)." -> * Core byte offset = PS byte address - 0x60000000; AXI AWADDR/ARADDR are 16-bit and decode 0x0000 ~ 0x014F (Core717 spec 7.1).
B24: * Word address = core byte offset / 4 (32-bit registers). Local address in DUT_ARINC_717 = word address - module base (starts from 0x00).
B25: * Reserved byte address 0x0000 ~ 0x014F: write ignored, read returns 0, response OKAY. 0x0150 ~ 0x03FF (outside core decode): response SLVERR.
B26: * Type (sheet ARINC_717): RW = read/write, RO = read only, WO = write only, X = unused byte lane (reads 0).

Sheet SYSCTRL
A1: Offset Word Address | B1: Type | C1: Register Name | D1: Bit[31] | E1: Bit[30] | F1: Bit[29] | G1: Bit[28] | H1: Bit[27] | I1: Bit[26] | J1: Bit[25] | K1: Bit[24] | L1: Field Description | M1: Value Description | N1: ="ARINC (Base address: "&Module_Address_Usage!$C$2&")" -> ARINC (Base address: 0x40000000)
D2: Bit[23] | E2: Bit[22] | F2: Bit[21] | G2: Bit[20] | H2: Bit[19] | I2: Bit[18] | J2: Bit[17] | K2: Bit[16]
D3: Bit[15] | E3: Bit[14] | F3: Bit[13] | G3: Bit[12] | H3: Bit[11] | I3: Bit[10] | J3: Bit[9] | K3: Bit[8] | N3: Address | P3: Initial Value | Q3: Usage | R3: PS (AXI) Byte Address
D4: Bit[7] | E4: Bit[6] | F4: Bit[5] | G4: Bit[4] | H4: Bit[3] | I4: Bit[2] | J4: Bit[1] | K4: Bit[0] | N4: Word | O4: Byte
D5: SYSCTRL Module (SYSCTRL_TOP / CPUIF_SYSCTRL) | L5: ="Module word address : "&Module_Address_Usage!$C$4&" ~ "&Module_Address_Usage!$D$4&" (local 0x00 ~ 0x"&DEC2HEX(HEX2DEC(MID(Module_Address_Usage!$D$4,3,5))-HEX2DEC(MID(Module_Address_Usage!$C$4,3,5)),2)&")"&CHAR(10)&"PS byte address : "&Module_Address_Usage!$I$4&" ~ "&Module_Address_Usage!$J$4 -> Module word address : 0x00000 ~ 0x0007F (local 0x00 ~ 0x7F) PS byte address : 0x4000_0000 ~ 0x4000_01FF
A9: 0x00000 | B9: X | C9: CLOCK_WIZ_RST | L9: CLOCK_WIZ_RST: clock_wiz_0 reset (clock_wiz_0.resetn = ~CLOCK_WIZ_RST) Clock: CLK_CPUIF (FCLK_CLK0) | M9: 0b0: release 0b1: reset (default) CLK_OUT1/CLK_OUT2 run only after SW writes 0b0 | N9: =CONCATENATE("0x",DEC2HEX(HEX2DEC(MID(Module_Address_Usage!$C$4,3,5))+HEX2DEC(MID($A9,3,5)),5)) -> 0x00000 | O9: =CONCATENATE("0x",DEC2HEX(HEX2DEC(MID($N$9,3,5))*4+3,6)) -> 0x000003 | P9: - | Q9: X | R9: =CONCATENATE("0x",LEFT(DEC2HEX(HEX2DEC(MID(Module_Address_Usage!$C$2,3,8))+HEX2DEC(MID($N$9,3,5))*4+0,8),4),"_",RIGHT(DEC2HEX(HEX2DEC(MID(Module_Address_Usage!$C$2,3,8))+HEX2DEC(MID($N$9,3,5))*4+0,8),4)) -> 0x4000_0000
B10: X | O10: =CONCATENATE("0x",DEC2HEX(HEX2DEC(MID($N$9,3,5))*4+2,6)) -> 0x000002 | P10: - | Q10: X
B11: X | O11: =CONCATENATE("0x",DEC2HEX(HEX2DEC(MID($N$9,3,5))*4+1,6)) -> 0x000001 | P11: - | Q11: X
B12: RW | K12: CLOCK_WIZ_RST | O12: =CONCATENATE("0x",DEC2HEX(HEX2DEC(MID($N$9,3,5))*4+0,6)) -> 0x000000 | P12: 0x01 | Q12: O
A13: 0x00001 | B13: X | C13: MISC_RST | L13: MISC_RST: MISC_TOP reset | M13: 0b0: release 0b1: reset (default) | N13: =CONCATENATE("0x",DEC2HEX(HEX2DEC(MID(Module_Address_Usage!$C$4,3,5))+HEX2DEC(MID($A13,3,5)),5)) -> 0x00001 | O13: =CONCATENATE("0x",DEC2HEX(HEX2DEC(MID($N$13,3,5))*4+3,6)) -> 0x000007 | P13: - | Q13: X | R13: =CONCATENATE("0x",LEFT(DEC2HEX(HEX2DEC(MID(Module_Address_Usage!$C$2,3,8))+HEX2DEC(MID($N$13,3,5))*4+0,8),4),"_",RIGHT(DEC2HEX(HEX2DEC(MID(Module_Address_Usage!$C$2,3,8))+HEX2DEC(MID($N$13,3,5))*4+0,8),4)) -> 0x4000_0004
B14: X | O14: =CONCATENATE("0x",DEC2HEX(HEX2DEC(MID($N$13,3,5))*4+2,6)) -> 0x000006 | P14: - | Q14: X
B15: X | O15: =CONCATENATE("0x",DEC2HEX(HEX2DEC(MID($N$13,3,5))*4+1,6)) -> 0x000005 | P15: - | Q15: X
B16: RW | K16: MISC_RST | O16: =CONCATENATE("0x",DEC2HEX(HEX2DEC(MID($N$13,3,5))*4+0,6)) -> 0x000004 | P16: 0x01 | Q16: O
A17: 0x00002 | B17: X | C17: CLK_FAIL_FLAG | L17: CLK_UNLOCK: Unlock flag for clock_wiz_0 (latched, clear on read) | M17: 0b1: Unlock, 0b0: Lock | N17: =CONCATENATE("0x",DEC2HEX(HEX2DEC(MID(Module_Address_Usage!$C$4,3,5))+HEX2DEC(MID($A17,3,5)),5)) -> 0x00002 | O17: =CONCATENATE("0x",DEC2HEX(HEX2DEC(MID($N$17,3,5))*4+3,6)) -> 0x00000B | P17: - | Q17: X | R17: =CONCATENATE("0x",LEFT(DEC2HEX(HEX2DEC(MID(Module_Address_Usage!$C$2,3,8))+HEX2DEC(MID($N$17,3,5))*4+0,8),4),"_",RIGHT(DEC2HEX(HEX2DEC(MID(Module_Address_Usage!$C$2,3,8))+HEX2DEC(MID($N$17,3,5))*4+0,8),4)) -> 0x4000_0008
B18: X | O18: =CONCATENATE("0x",DEC2HEX(HEX2DEC(MID($N$17,3,5))*4+2,6)) -> 0x00000A | P18: - | Q18: X
B19: X | O19: =CONCATENATE("0x",DEC2HEX(HEX2DEC(MID($N$17,3,5))*4+1,6)) -> 0x000009 | P19: - | Q19: X
B20: RO | K20: CLK_UNLOCK | O20: =CONCATENATE("0x",DEC2HEX(HEX2DEC(MID($N$17,3,5))*4+0,6)) -> 0x000008 | P20: - | Q20: O
A21: 0x00003 | B21: X | C21: CLK_FAIL_STS | L21: CLK_UNLOCK: Unlock status for clock_wiz_0 | M21: 0b1: Unlock, 0b0: Lock | N21: =CONCATENATE("0x",DEC2HEX(HEX2DEC(MID(Module_Address_Usage!$C$4,3,5))+HEX2DEC(MID($A21,3,5)),5)) -> 0x00003 | O21: =CONCATENATE("0x",DEC2HEX(HEX2DEC(MID($N$21,3,5))*4+3,6)) -> 0x00000F | P21: - | Q21: X | R21: =CONCATENATE("0x",LEFT(DEC2HEX(HEX2DEC(MID(Module_Address_Usage!$C$2,3,8))+HEX2DEC(MID($N$21,3,5))*4+0,8),4),"_",RIGHT(DEC2HEX(HEX2DEC(MID(Module_Address_Usage!$C$2,3,8))+HEX2DEC(MID($N$21,3,5))*4+0,8),4)) -> 0x4000_000C
B22: X | O22: =CONCATENATE("0x",DEC2HEX(HEX2DEC(MID($N$21,3,5))*4+2,6)) -> 0x00000E | P22: - | Q22: X
B23: X | O23: =CONCATENATE("0x",DEC2HEX(HEX2DEC(MID($N$21,3,5))*4+1,6)) -> 0x00000D | P23: - | Q23: X
B24: RO | K24: CLK_UNLOCK | O24: =CONCATENATE("0x",DEC2HEX(HEX2DEC(MID($N$21,3,5))*4+0,6)) -> 0x00000C | P24: - | Q24: O
A25: 0x00004 ~ 0x0007F | B25: X | C25: Reserved | L25: Reserved | M25: Write ignored, read returns 0x0000_0000 | N25: =CONCATENATE("0x",DEC2HEX(HEX2DEC(MID(Module_Address_Usage!$C$4,3,5))+HEX2DEC(MID($A25,3,5)),5))&CHAR(10)&"~ "&CONCATENATE("0x",DEC2HEX(HEX2DEC(MID(Module_Address_Usage!$C$4,3,5))+HEX2DEC(MID($A25,13,5)),5)) -> 0x00004 ~ 0x0007F | O25: =CONCATENATE("0x",DEC2HEX(HEX2DEC(MID(CONCATENATE("0x",DEC2HEX(HEX2DEC(MID(Module_Address_Usage!$C$4,3,5))+HEX2DEC(MID($A25,3,5)),5)),3,5))*4+0,6))&CHAR(10)&"~ "&CONCATENATE("0x",DEC2HEX(HEX2DEC(MID(CONCATENATE("0x",DEC2HEX(HEX2DEC(MID(Module_Address_Usage!$C$4,3,5))+HEX2DEC(MID($A25,13,5)),5)),3,5))*4+3,6)) -> 0x000010 ~ 0x0001FF | P25: - | Q25: X | R25: =CONCATENATE("0x",LEFT(DEC2HEX(HEX2DEC(MID(Module_Address_Usage!$C$2,3,8))+HEX2DEC(MID(CONCATENATE("0x",DEC2HEX(HEX2DEC(MID(Module_Address_Usage!$C$4,3,5))+HEX2DEC(MID($A25,3,5)),5)),3,5))*4+0,8),4),"_",RIGHT(DEC2HEX(HEX2DEC(MID(Module_Address_Usage!$C$2,3,8))+HEX2DEC(MID(CONCATENATE("0x",DEC2HEX(HEX2DEC(MID(Module_Address_Usage!$C$4,3,5))+HEX2DEC(MID($A25,3,5)),5)),3,5))*4+0,8),4))&CHAR(10)&"~ "&CONCATENATE("0x",LEFT(DEC2HEX(HEX2DEC(MID(Module_Address_Usage!$C$2,3,8))+HEX2DEC(MID(CONCATENATE("0x",DEC2HEX(HEX2DEC(MID(Module_Address_Usage!$C$4,3,5))+HEX2DEC(MID($A25,13,5)),5)),3,5))*4+3,8),4),"_",RIGHT(DEC2HEX(HEX2DEC(MID(Module_Address_Usage!$C$2,3,8))+HEX2DEC(MID(CONCATENATE("0x",DEC2HEX(HEX2DEC(MID(Module_Address_Usage!$C$4,3,5))+HEX2DEC(MID($A25,13,5)),5)),3,5))*4+3,8),4)) -> 0x4000_0010 ~ 0x4000_01FF

Sheet MISC
A1: Offset Word Address | B1: Type | C1: Register Name | D1: Bit[31] | E1: Bit[30] | F1: Bit[29] | G1: Bit[28] | H1: Bit[27] | I1: Bit[26] | J1: Bit[25] | K1: Bit[24] | L1: Field Description | M1: Value Description | N1: ="ARINC (Base address: "&Module_Address_Usage!$C$2&")" -> ARINC (Base address: 0x40000000)
D2: Bit[23] | E2: Bit[22] | F2: Bit[21] | G2: Bit[20] | H2: Bit[19] | I2: Bit[18] | J2: Bit[17] | K2: Bit[16]
D3: Bit[15] | E3: Bit[14] | F3: Bit[13] | G3: Bit[12] | H3: Bit[11] | I3: Bit[10] | J3: Bit[9] | K3: Bit[8] | N3: Address | P3: Initial Value | Q3: Usage | R3: PS (AXI) Byte Address
D4: Bit[7] | E4: Bit[6] | F4: Bit[5] | G4: Bit[4] | H4: Bit[3] | I4: Bit[2] | J4: Bit[1] | K4: Bit[0] | N4: Word | O4: Byte
D5: MISC Module (MISC_TOP / CPUIF_MISC) | L5: ="Module word address : "&Module_Address_Usage!$C$5&" ~ "&Module_Address_Usage!$D$5&" (local 0x00 ~ 0x"&DEC2HEX(HEX2DEC(MID(Module_Address_Usage!$D$5,3,5))-HEX2DEC(MID(Module_Address_Usage!$C$5,3,5)),2)&")"&CHAR(10)&"PS byte address : "&Module_Address_Usage!$I$5&" ~ "&Module_Address_Usage!$J$5 -> Module word address : 0x00080 ~ 0x000FF (local 0x00 ~ 0x7F) PS byte address : 0x4000_0200 ~ 0x4000_03FF
A9: 0x00000 | B9: X | C9: PORT_IN_CLK_CPU_0 | L9: PORT_IN_CLK_CPU_0[3:0]: port_in_clk_cpu_0 input Asynchronous, 2-FF sync to CLK_CPUIF | M9: Input level of port_in_clk_cpu_0[3:0] (SYSTEM_TOP: w_port_in_clk_cpu_0 not connected yet - TODO) | N9: =CONCATENATE("0x",DEC2HEX(HEX2DEC(MID(Module_Address_Usage!$C$5,3,5))+HEX2DEC(MID($A9,3,5)),5)) -> 0x00080 | O9: =CONCATENATE("0x",DEC2HEX(HEX2DEC(MID($N$9,3,5))*4+3,6)) -> 0x000203 | P9: - | Q9: X | R9: =CONCATENATE("0x",LEFT(DEC2HEX(HEX2DEC(MID(Module_Address_Usage!$C$2,3,8))+HEX2DEC(MID($N$9,3,5))*4+0,8),4),"_",RIGHT(DEC2HEX(HEX2DEC(MID(Module_Address_Usage!$C$2,3,8))+HEX2DEC(MID($N$9,3,5))*4+0,8),4)) -> 0x4000_0200
B10: X | O10: =CONCATENATE("0x",DEC2HEX(HEX2DEC(MID($N$9,3,5))*4+2,6)) -> 0x000202 | P10: - | Q10: X
B11: X | O11: =CONCATENATE("0x",DEC2HEX(HEX2DEC(MID($N$9,3,5))*4+1,6)) -> 0x000201 | P11: - | Q11: X
B12: RO | H12: PORT_IN_CLK_CPU_0[3:0] | O12: =CONCATENATE("0x",DEC2HEX(HEX2DEC(MID($N$9,3,5))*4+0,6)) -> 0x000200 | P12: - | Q12: O
A13: 0x00001 | B13: X | C13: PORT_IN_CLK_CPU_1 | L13: PORT_IN_CLK_CPU_1[3:0]: port_in_clk_cpu_1 input Asynchronous, 2-FF sync to CLK_CPUIF | M13: Input level of port_in_clk_cpu_1[3:0] (SYSTEM_TOP: w_port_in_clk_cpu_1 not connected yet - TODO) | N13: =CONCATENATE("0x",DEC2HEX(HEX2DEC(MID(Module_Address_Usage!$C$5,3,5))+HEX2DEC(MID($A13,3,5)),5)) -> 0x00081 | O13: =CONCATENATE("0x",DEC2HEX(HEX2DEC(MID($N$13,3,5))*4+3,6)) -> 0x000207 | P13: - | Q13: X | R13: =CONCATENATE("0x",LEFT(DEC2HEX(HEX2DEC(MID(Module_Address_Usage!$C$2,3,8))+HEX2DEC(MID($N$13,3,5))*4+0,8),4),"_",RIGHT(DEC2HEX(HEX2DEC(MID(Module_Address_Usage!$C$2,3,8))+HEX2DEC(MID($N$13,3,5))*4+0,8),4)) -> 0x4000_0204
B14: X | O14: =CONCATENATE("0x",DEC2HEX(HEX2DEC(MID($N$13,3,5))*4+2,6)) -> 0x000206 | P14: - | Q14: X
B15: X | O15: =CONCATENATE("0x",DEC2HEX(HEX2DEC(MID($N$13,3,5))*4+1,6)) -> 0x000205 | P15: - | Q15: X
B16: RO | H16: PORT_IN_CLK_CPU_1[3:0] | O16: =CONCATENATE("0x",DEC2HEX(HEX2DEC(MID($N$13,3,5))*4+0,6)) -> 0x000204 | P16: - | Q16: O
A17: 0x00002 | B17: X | C17: PORT_IN_CLK_CPU_2 | L17: PORT_IN_CLK_CPU_2[3:0]: port_in_clk_cpu_2 input Asynchronous, 2-FF sync to CLK_CPUIF | M17: Input level of port_in_clk_cpu_2[3:0] (SYSTEM_TOP: w_port_in_clk_cpu_2 not connected yet - TODO) | N17: =CONCATENATE("0x",DEC2HEX(HEX2DEC(MID(Module_Address_Usage!$C$5,3,5))+HEX2DEC(MID($A17,3,5)),5)) -> 0x00082 | O17: =CONCATENATE("0x",DEC2HEX(HEX2DEC(MID($N$17,3,5))*4+3,6)) -> 0x00020B | P17: - | Q17: X | R17: =CONCATENATE("0x",LEFT(DEC2HEX(HEX2DEC(MID(Module_Address_Usage!$C$2,3,8))+HEX2DEC(MID($N$17,3,5))*4+0,8),4),"_",RIGHT(DEC2HEX(HEX2DEC(MID(Module_Address_Usage!$C$2,3,8))+HEX2DEC(MID($N$17,3,5))*4+0,8),4)) -> 0x4000_0208
B18: X | O18: =CONCATENATE("0x",DEC2HEX(HEX2DEC(MID($N$17,3,5))*4+2,6)) -> 0x00020A | P18: - | Q18: X
B19: X | O19: =CONCATENATE("0x",DEC2HEX(HEX2DEC(MID($N$17,3,5))*4+1,6)) -> 0x000209 | P19: - | Q19: X
B20: RO | H20: PORT_IN_CLK_CPU_2[3:0] | O20: =CONCATENATE("0x",DEC2HEX(HEX2DEC(MID($N$17,3,5))*4+0,6)) -> 0x000208 | P20: - | Q20: O
A21: 0x00003 | B21: X | C21: PORT_OUT_CLK_CPU_0 | L21: PORT_OUT_CLK_CPU_0[3:0]: port_out_clk_cpu_0 output Clock: CLK_CPUIF | M21: Value driven on port_out_clk_cpu_0[3:0] Default 0x0 | N21: =CONCATENATE("0x",DEC2HEX(HEX2DEC(MID(Module_Address_Usage!$C$5,3,5))+HEX2DEC(MID($A21,3,5)),5)) -> 0x00083 | O21: =CONCATENATE("0x",DEC2HEX(HEX2DEC(MID($N$21,3,5))*4+3,6)) -> 0x00020F | P21: - | Q21: X | R21: =CONCATENATE("0x",LEFT(DEC2HEX(HEX2DEC(MID(Module_Address_Usage!$C$2,3,8))+HEX2DEC(MID($N$21,3,5))*4+0,8),4),"_",RIGHT(DEC2HEX(HEX2DEC(MID(Module_Address_Usage!$C$2,3,8))+HEX2DEC(MID($N$21,3,5))*4+0,8),4)) -> 0x4000_020C
B22: X | O22: =CONCATENATE("0x",DEC2HEX(HEX2DEC(MID($N$21,3,5))*4+2,6)) -> 0x00020E | P22: - | Q22: X
B23: X | O23: =CONCATENATE("0x",DEC2HEX(HEX2DEC(MID($N$21,3,5))*4+1,6)) -> 0x00020D | P23: - | Q23: X
B24: RW | H24: PORT_OUT_CLK_CPU_0[3:0] | O24: =CONCATENATE("0x",DEC2HEX(HEX2DEC(MID($N$21,3,5))*4+0,6)) -> 0x00020C | P24: 0x00 | Q24: O
A25: 0x00004 | B25: X | C25: PORT_OUT_CLK_CPU_1 | L25: PORT_OUT_CLK_CPU_1[3:0]: port_out_clk_cpu_1 output Clock: CLK_CPUIF | M25: Value driven on port_out_clk_cpu_1[3:0] Default 0x0 | N25: =CONCATENATE("0x",DEC2HEX(HEX2DEC(MID(Module_Address_Usage!$C$5,3,5))+HEX2DEC(MID($A25,3,5)),5)) -> 0x00084 | O25: =CONCATENATE("0x",DEC2HEX(HEX2DEC(MID($N$25,3,5))*4+3,6)) -> 0x000213 | P25: - | Q25: X | R25: =CONCATENATE("0x",LEFT(DEC2HEX(HEX2DEC(MID(Module_Address_Usage!$C$2,3,8))+HEX2DEC(MID($N$25,3,5))*4+0,8),4),"_",RIGHT(DEC2HEX(HEX2DEC(MID(Module_Address_Usage!$C$2,3,8))+HEX2DEC(MID($N$25,3,5))*4+0,8),4)) -> 0x4000_0210
B26: X | O26: =CONCATENATE("0x",DEC2HEX(HEX2DEC(MID($N$25,3,5))*4+2,6)) -> 0x000212 | P26: - | Q26: X
B27: X | O27: =CONCATENATE("0x",DEC2HEX(HEX2DEC(MID($N$25,3,5))*4+1,6)) -> 0x000211 | P27: - | Q27: X
B28: RW | H28: PORT_OUT_CLK_CPU_1[3:0] | O28: =CONCATENATE("0x",DEC2HEX(HEX2DEC(MID($N$25,3,5))*4+0,6)) -> 0x000210 | P28: 0x00 | Q28: O
A29: 0x00005 | B29: X | C29: PORT_OUT_CLK_CPU_2 | L29: PORT_OUT_CLK_CPU_2[3:0]: port_out_clk_cpu_2 output Clock: CLK_CPUIF | M29: Value driven on port_out_clk_cpu_2[3:0] Default 0x0 | N29: =CONCATENATE("0x",DEC2HEX(HEX2DEC(MID(Module_Address_Usage!$C$5,3,5))+HEX2DEC(MID($A29,3,5)),5)) -> 0x00085 | O29: =CONCATENATE("0x",DEC2HEX(HEX2DEC(MID($N$29,3,5))*4+3,6)) -> 0x000217 | P29: - | Q29: X | R29: =CONCATENATE("0x",LEFT(DEC2HEX(HEX2DEC(MID(Module_Address_Usage!$C$2,3,8))+HEX2DEC(MID($N$29,3,5))*4+0,8),4),"_",RIGHT(DEC2HEX(HEX2DEC(MID(Module_Address_Usage!$C$2,3,8))+HEX2DEC(MID($N$29,3,5))*4+0,8),4)) -> 0x4000_0214
B30: X | O30: =CONCATENATE("0x",DEC2HEX(HEX2DEC(MID($N$29,3,5))*4+2,6)) -> 0x000216 | P30: - | Q30: X
B31: X | O31: =CONCATENATE("0x",DEC2HEX(HEX2DEC(MID($N$29,3,5))*4+1,6)) -> 0x000215 | P31: - | Q31: X
B32: RW | H32: PORT_OUT_CLK_CPU_2[3:0] | O32: =CONCATENATE("0x",DEC2HEX(HEX2DEC(MID($N$29,3,5))*4+0,6)) -> 0x000214 | P32: 0x00 | Q32: O
A33: 0x00006 ~ 0x0000F | B33: X | C33: Reserved | L33: Reserved | M33: Write ignored, read returns 0x0000_0000 | N33: =CONCATENATE("0x",DEC2HEX(HEX2DEC(MID(Module_Address_Usage!$C$5,3,5))+HEX2DEC(MID($A33,3,5)),5))&CHAR(10)&"~ "&CONCATENATE("0x",DEC2HEX(HEX2DEC(MID(Module_Address_Usage!$C$5,3,5))+HEX2DEC(MID($A33,13,5)),5)) -> 0x00086 ~ 0x0008F | O33: =CONCATENATE("0x",DEC2HEX(HEX2DEC(MID(CONCATENATE("0x",DEC2HEX(HEX2DEC(MID(Module_Address_Usage!$C$5,3,5))+HEX2DEC(MID($A33,3,5)),5)),3,5))*4+0,6))&CHAR(10)&"~ "&CONCATENATE("0x",DEC2HEX(HEX2DEC(MID(CONCATENATE("0x",DEC2HEX(HEX2DEC(MID(Module_Address_Usage!$C$5,3,5))+HEX2DEC(MID($A33,13,5)),5)),3,5))*4+3,6)) -> 0x000218 ~ 0x00023F | P33: - | Q33: X | R33: =CONCATENATE("0x",LEFT(DEC2HEX(HEX2DEC(MID(Module_Address_Usage!$C$2,3,8))+HEX2DEC(MID(CONCATENATE("0x",DEC2HEX(HEX2DEC(MID(Module_Address_Usage!$C$5,3,5))+HEX2DEC(MID($A33,3,5)),5)),3,5))*4+0,8),4),"_",RIGHT(DEC2HEX(HEX2DEC(MID(Module_Address_Usage!$C$2,3,8))+HEX2DEC(MID(CONCATENATE("0x",DEC2HEX(HEX2DEC(MID(Module_Address_Usage!$C$5,3,5))+HEX2DEC(MID($A33,3,5)),5)),3,5))*4+0,8),4))&CHAR(10)&"~ "&CONCATENATE("0x",LEFT(DEC2HEX(HEX2DEC(MID(Module_Address_Usage!$C$2,3,8))+HEX2DEC(MID(CONCATENATE("0x",DEC2HEX(HEX2DEC(MID(Module_Address_Usage!$C$5,3,5))+HEX2DEC(MID($A33,13,5)),5)),3,5))*4+3,8),4),"_",RIGHT(DEC2HEX(HEX2DEC(MID(Module_Address_Usage!$C$2,3,8))+HEX2DEC(MID(CONCATENATE("0x",DEC2HEX(HEX2DEC(MID(Module_Address_Usage!$C$5,3,5))+HEX2DEC(MID($A33,13,5)),5)),3,5))*4+3,8),4)) -> 0x4000_0218 ~ 0x4000_023F
A34: 0x00010 | B34: X | C34: PORT_IN_CLK_OUT1_0 | L34: PORT_IN_CLK_OUT1_0[3:0]: port_in_clk_out1_0 input Registered in CLK_OUT1 (48 MHz), 2-FF sync to CLK_CPUIF | M34: Input level of port_in_clk_out1_0[3:0] (SYSTEM_TOP: w_port_in_clk_out1_0 not connected yet - TODO) | N34: =CONCATENATE("0x",DEC2HEX(HEX2DEC(MID(Module_Address_Usage!$C$5,3,5))+HEX2DEC(MID($A34,3,5)),5)) -> 0x00090 | O34: =CONCATENATE("0x",DEC2HEX(HEX2DEC(MID($N$34,3,5))*4+3,6)) -> 0x000243 | P34: - | Q34: X | R34: =CONCATENATE("0x",LEFT(DEC2HEX(HEX2DEC(MID(Module_Address_Usage!$C$2,3,8))+HEX2DEC(MID($N$34,3,5))*4+0,8),4),"_",RIGHT(DEC2HEX(HEX2DEC(MID(Module_Address_Usage!$C$2,3,8))+HEX2DEC(MID($N$34,3,5))*4+0,8),4)) -> 0x4000_0240
B35: X | O35: =CONCATENATE("0x",DEC2HEX(HEX2DEC(MID($N$34,3,5))*4+2,6)) -> 0x000242 | P35: - | Q35: X
B36: X | O36: =CONCATENATE("0x",DEC2HEX(HEX2DEC(MID($N$34,3,5))*4+1,6)) -> 0x000241 | P36: - | Q36: X
B37: RO | H37: PORT_IN_CLK_OUT1_0[3:0] | O37: =CONCATENATE("0x",DEC2HEX(HEX2DEC(MID($N$34,3,5))*4+0,6)) -> 0x000240 | P37: - | Q37: O
A38: 0x00011 | B38: X | C38: PORT_IN_CLK_OUT1_1 | L38: PORT_IN_CLK_OUT1_1[3:0]: port_in_clk_out1_1 input Registered in CLK_OUT1 (48 MHz), 2-FF sync to CLK_CPUIF | M38: Input level of port_in_clk_out1_1[3:0] (SYSTEM_TOP: w_port_in_clk_out1_1 not connected yet - TODO) | N38: =CONCATENATE("0x",DEC2HEX(HEX2DEC(MID(Module_Address_Usage!$C$5,3,5))+HEX2DEC(MID($A38,3,5)),5)) -> 0x00091 | O38: =CONCATENATE("0x",DEC2HEX(HEX2DEC(MID($N$38,3,5))*4+3,6)) -> 0x000247 | P38: - | Q38: X | R38: =CONCATENATE("0x",LEFT(DEC2HEX(HEX2DEC(MID(Module_Address_Usage!$C$2,3,8))+HEX2DEC(MID($N$38,3,5))*4+0,8),4),"_",RIGHT(DEC2HEX(HEX2DEC(MID(Module_Address_Usage!$C$2,3,8))+HEX2DEC(MID($N$38,3,5))*4+0,8),4)) -> 0x4000_0244
B39: X | O39: =CONCATENATE("0x",DEC2HEX(HEX2DEC(MID($N$38,3,5))*4+2,6)) -> 0x000246 | P39: - | Q39: X
B40: X | O40: =CONCATENATE("0x",DEC2HEX(HEX2DEC(MID($N$38,3,5))*4+1,6)) -> 0x000245 | P40: - | Q40: X
B41: RO | H41: PORT_IN_CLK_OUT1_1[3:0] | O41: =CONCATENATE("0x",DEC2HEX(HEX2DEC(MID($N$38,3,5))*4+0,6)) -> 0x000244 | P41: - | Q41: O
A42: 0x00012 | B42: X | C42: PORT_IN_CLK_OUT1_2 | L42: PORT_IN_CLK_OUT1_2[3:0]: port_in_clk_out1_2 input Registered in CLK_OUT1 (48 MHz), 2-FF sync to CLK_CPUIF | M42: Input level of port_in_clk_out1_2[3:0] (SYSTEM_TOP: w_port_in_clk_out1_2 not connected yet - TODO) | N42: =CONCATENATE("0x",DEC2HEX(HEX2DEC(MID(Module_Address_Usage!$C$5,3,5))+HEX2DEC(MID($A42,3,5)),5)) -> 0x00092 | O42: =CONCATENATE("0x",DEC2HEX(HEX2DEC(MID($N$42,3,5))*4+3,6)) -> 0x00024B | P42: - | Q42: X | R42: =CONCATENATE("0x",LEFT(DEC2HEX(HEX2DEC(MID(Module_Address_Usage!$C$2,3,8))+HEX2DEC(MID($N$42,3,5))*4+0,8),4),"_",RIGHT(DEC2HEX(HEX2DEC(MID(Module_Address_Usage!$C$2,3,8))+HEX2DEC(MID($N$42,3,5))*4+0,8),4)) -> 0x4000_0248
B43: X | O43: =CONCATENATE("0x",DEC2HEX(HEX2DEC(MID($N$42,3,5))*4+2,6)) -> 0x00024A | P43: - | Q43: X
...

Sheet ARINC_717
A1: Offset Word Address | B1: Type | C1: Register Name | D1: Bit[31] | E1: Bit[30] | F1: Bit[29] | G1: Bit[28] | H1: Bit[27] | I1: Bit[26] | J1: Bit[25] | K1: Bit[24] | L1: Field Description | M1: Value Description | N1: ="DUT_ARINC_717 (Base address: "&Module_Address_Usage!$C$18&")" -> DUT_ARINC_717 (Base address: 0x60000000)
D2: Bit[23] | E2: Bit[22] | F2: Bit[21] | G2: Bit[20] | H2: Bit[19] | I2: Bit[18] | J2: Bit[17] | K2: Bit[16]
D3: Bit[15] | E3: Bit[14] | F3: Bit[13] | G3: Bit[12] | H3: Bit[11] | I3: Bit[10] | J3: Bit[9] | K3: Bit[8] | N3: Address | P3: Initial Value | Q3: Usage | R3: PS (AXI) Byte Address
D4: Bit[7] | E4: Bit[6] | F4: Bit[5] | G4: Bit[4] | H4: Bit[3] | I4: Bit[2] | J4: Bit[1] | K4: Bit[0] | N4: Word | O4: Byte
D5: ARINC_717 Module (DUT_ARINC_717 / Core717 AXI4-Lite) | L5: ="Module word address : "&Module_Address_Usage!$C$20&" ~ "&Module_Address_Usage!$D$20&" (local 0x00 ~ 0x"&DEC2HEX(HEX2DEC(MID(Module_Address_Usage!$D$20,3,5))-HEX2DEC(MID(Module_Address_Usage!$C$20,3,5)),2)&")"&CHAR(10)&"PS byte address : "&Module_Address_Usage!$I$20&" ~ "&Module_Address_Usage!$J$20 -> Module word address : 0x00000 ~ 0x000FF (local 0x00 ~ 0xFF) PS byte address : 0x6000_0000 ~ 0x6000_03FF
A9: 0x00000 | B9: RO | C9: CORE_VERSION | D9: MAJOR[15:8] | L9: MAJOR[15:0]: RTL major version MINOR[15:0]: RTL minor version | M9: Constant 0x0001_0000 (v1.0) Write returns SLVERR | N9: =CONCATENATE("0x",DEC2HEX(HEX2DEC(MID(Module_Address_Usage!$C$20,3,5))+HEX2DEC(MID($A9,3,5)),5)) -> 0x00000 | O9: =CONCATENATE("0x",DEC2HEX(HEX2DEC(MID($N$9,3,5))*4+3,6)) -> 0x000003 | P9: - | Q9: O | R9: =CONCATENATE("0x",LEFT(DEC2HEX(HEX2DEC(MID(Module_Address_Usage!$C$18,3,8))+HEX2DEC(MID($N$9,3,5))*4+0,8),4),"_",RIGHT(DEC2HEX(HEX2DEC(MID(Module_Address_Usage!$C$18,3,8))+HEX2DEC(MID($N$9,3,5))*4+0,8),4)) -> 0x6000_0000
B10: RO | D10: MAJOR[7:0] | O10: =CONCATENATE("0x",DEC2HEX(HEX2DEC(MID($N$9,3,5))*4+2,6)) -> 0x000002 | P10: - | Q10: O
B11: RO | D11: MINOR[15:8] | O11: =CONCATENATE("0x",DEC2HEX(HEX2DEC(MID($N$9,3,5))*4+1,6)) -> 0x000001 | P11: - | Q11: O
B12: RO | D12: MINOR[7:0] | O12: =CONCATENATE("0x",DEC2HEX(HEX2DEC(MID($N$9,3,5))*4+0,6)) -> 0x000000 | P12: - | Q12: O
A13: 0x00001 | B13: X | C13: GLOBAL_CTRL | L13: SOFT_RESET: soft reset, self-clears when done GLOBAL_EN: core enable TX_EN / RX_EN: TX / RX path enable IRQ_ENABLE: aggregated irq output enable INJ_DST: pattern injector destination | M13: 0b0: disable / idle (default) 0b1: enable / start INJ_DST 0b0: TX pins, 0b1: RX input Poll SOFT_RESET until 0b0 before config | N13: =CONCATENATE("0x",DEC2HEX(HEX2DEC(MID(Module_Address_Usage!$C$20,3,5))+HEX2DEC(MID($A13,3,5)),5)) -> 0x00001 | O13: =CONCATENATE("0x",DEC2HEX(HEX2DEC(MID($N$13,3,5))*4+3,6)) -> 0x000007 | P13: - | Q13: X | R13: =CONCATENATE("0x",LEFT(DEC2HEX(HEX2DEC(MID(Module_Address_Usage!$C$18,3,8))+HEX2DEC(MID($N$13,3,5))*4+0,8),4),"_",RIGHT(DEC2HEX(HEX2DEC(MID(Module_Address_Usage!$C$18,3,8))+HEX2DEC(MID($N$13,3,5))*4+0,8),4)) -> 0x6000_0004
B14: X | O14: =CONCATENATE("0x",DEC2HEX(HEX2DEC(MID($N$13,3,5))*4+2,6)) -> 0x000006 | P14: - | Q14: X
B15: X | O15: =CONCATENATE("0x",DEC2HEX(HEX2DEC(MID($N$13,3,5))*4+1,6)) -> 0x000005 | P15: - | Q15: X
B16: RW | F16: INJ_DST | G16: IRQ_ENABLE | H16: RX_EN | I16: TX_EN | J16: GLOBAL_EN | K16: SOFT_RESET | O16: =CONCATENATE("0x",DEC2HEX(HEX2DEC(MID($N$13,3,5))*4+0,6)) -> 0x000004 | P16: 0x00 | Q16: O
A17: 0x00002 | B17: X | C17: GLOBAL_STATUS | L17: CORE_PENDING: IRQ_SOURCE is not 0 CLR_BUSY: SOFT_RESET or FIFO clear in progress | M17: 0b0: idle 0b1: pending / busy | N17: =CONCATENATE("0x",DEC2HEX(HEX2DEC(MID(Module_Address_Usage!$C$20,3,5))+HEX2DEC(MID($A17,3,5)),5)) -> 0x00002 | O17: =CONCATENATE("0x",DEC2HEX(HEX2DEC(MID($N$17,3,5))*4+3,6)) -> 0x00000B | P17: - | Q17: X | R17: =CONCATENATE("0x",LEFT(DEC2HEX(HEX2DEC(MID(Module_Address_Usage!$C$18,3,8))+HEX2DEC(MID($N$17,3,5))*4+0,8),4),"_",RIGHT(DEC2HEX(HEX2DEC(MID(Module_Address_Usage!$C$18,3,8))+HEX2DEC(MID($N$17,3,5))*4+0,8),4)) -> 0x6000_0008
B18: X | O18: =CONCATENATE("0x",DEC2HEX(HEX2DEC(MID($N$17,3,5))*4+2,6)) -> 0x00000A | P18: - | Q18: X
B19: X | O19: =CONCATENATE("0x",DEC2HEX(HEX2DEC(MID($N$17,3,5))*4+1,6)) -> 0x000009 | P19: - | Q19: X
B20: RO | J20: CLR_BUSY | K20: CORE_PENDING | O20: =CONCATENATE("0x",DEC2HEX(HEX2DEC(MID($N$17,3,5))*4+0,6)) -> 0x000008 | P20: - | Q20: O
A21: 0x00003 | B21: X | C21: IRQ_SOURCE | L21: [3:0]: TX_IRQ_STATUS AND TX_IRQ_ENABLE [22:16]: RX_IRQ_STATUS AND RX_IRQ_ENABLE Not gated by GLOBAL_CTRL.IRQ_ENABLE | M21: 0b0: no request 0b1: source requests irq Clear by W1C on TX/RX_IRQ_STATUS | N21: =CONCATENATE("0x",DEC2HEX(HEX2DEC(MID(Module_Address_Usage!$C$20,3,5))+HEX2DEC(MID($A21,3,5)),5)) -> 0x00003 | O21: =CONCATENATE("0x",DEC2HEX(HEX2DEC(MID($N$21,3,5))*4+3,6)) -> 0x00000F | P21: - | Q21: X | R21: =CONCATENATE("0x",LEFT(DEC2HEX(HEX2DEC(MID(Module_Address_Usage!$C$18,3,8))+HEX2DEC(MID($N$21,3,5))*4+0,8),4),"_",RIGHT(DEC2HEX(HEX2DEC(MID(Module_Address_Usage!$C$18,3,8))+HEX2DEC(MID($N$21,3,5))*4+0,8),4)) -> 0x6000_000C
B22: RO | E22: RX_BIT_ERR | F22: RX_INSYNC_LOST | G22: RX_MATCH | H22: RX_OVERFLOW | I22: RX_FULL | J22: RX_HALF | K22: RX_EMPTY | O22: =CONCATENATE("0x",DEC2HEX(HEX2DEC(MID($N$21,3,5))*4+2,6)) -> 0x00000E | P22: - | Q22: O
B23: X | O23: =CONCATENATE("0x",DEC2HEX(HEX2DEC(MID($N$21,3,5))*4+1,6)) -> 0x00000D | P23: - | Q23: X
B24: RO | H24: TX_UNDERRUN | I24: TX_FULL | J24: TX_LOW | K24: TX_EMPTY | O24: =CONCATENATE("0x",DEC2HEX(HEX2DEC(MID($N$21,3,5))*4+0,6)) -> 0x00000C | P24: - | Q24: O
A25: 0x00004 ~ 0x00007 | B25: X | C25: Reserved | L25: Reserved | M25: Write ignored, read returns 0x0000_0000 | N25: =CONCATENATE("0x",DEC2HEX(HEX2DEC(MID(Module_Address_Usage!$C$20,3,5))+HEX2DEC(MID($A25,3,5)),5))&CHAR(10)&"~ "&CONCATENATE("0x",DEC2HEX(HEX2DEC(MID(Module_Address_Usage!$C$20,3,5))+HEX2DEC(MID($A25,13,5)),5)) -> 0x00004 ~ 0x00007 | O25: =CONCATENATE("0x",DEC2HEX(HEX2DEC(MID(CONCATENATE("0x",DEC2HEX(HEX2DEC(MID(Module_Address_Usage!$C$20,3,5))+HEX2DEC(MID($A25,3,5)),5)),3,5))*4+0,6))&CHAR(10)&"~ "&CONCATENATE("0x",DEC2HEX(HEX2DEC(MID(CONCATENATE("0x",DEC2HEX(HEX2DEC(MID(Module_Address_Usage!$C$20,3,5))+HEX2DEC(MID($A25,13,5)),5)),3,5))*4+3,6)) -> 0x000010 ~ 0x00001F | P25: - | Q25: X | R25: =CONCATENATE("0x",LEFT(DEC2HEX(HEX2DEC(MID(Module_Address_Usage!$C$18,3,8))+HEX2DEC(MID(CONCATENATE("0x",DEC2HEX(HEX2DEC(MID(Module_Address_Usage!$C$20,3,5))+HEX2DEC(MID($A25,3,5)),5)),3,5))*4+0,8),4),"_",RIGHT(DEC2HEX(HEX2DEC(MID(Module_Address_Usage!$C$18,3,8))+HEX2DEC(MID(CONCATENATE("0x",DEC2HEX(HEX2DEC(MID(Module_Address_Usage!$C$20,3,5))+HEX2DEC(MID($A25,3,5)),5)),3,5))*4+0,8),4))&CHAR(10)&"~ "&CONCATENATE("0x",LEFT(DEC2HEX(HEX2DEC(MID(Module_Address_Usage!$C$18,3,8))+HEX2DEC(MID(CONCATENATE("0x",DEC2HEX(HEX2DEC(MID(Module_Address_Usage!$C$20,3,5))+HEX2DEC(MID($A25,13,5)),5)),3,5))*4+3,8),4),"_",RIGHT(DEC2HEX(HEX2DEC(MID(Module_Address_Usage!$C$18,3,8))+HEX2DEC(MID(CONCATENATE("0x",DEC2HEX(HEX2DEC(MID(Module_Address_Usage!$C$20,3,5))+HEX2DEC(MID($A25,13,5)),5)),3,5))*4+3,8),4)) -> 0x6000_0010 ~ 0x6000_001F
A26: 0x00008 | B26: X | C26: TX_CTRL | L26: SYNC_INS_MODE: sync word insertion mode TX_RATE[3:0]: TX word-rate select (spec Table 5) Applied only while tx_active = 0 | M26: SYNC_INS_MODE 0b0: software inserts sync SYNC_INS_MODE 0b1: hardware inserts TX_SYNCx TX_RATE 0x8 ~ 0xF: as 0x0 (64 wps) | N26: =CONCATENATE("0x",DEC2HEX(HEX2DEC(MID(Module_Address_Usage!$C$20,3,5))+HEX2DEC(MID($A26,3,5)),5)) -> 0x00008 | O26: =CONCATENATE("0x",DEC2HEX(HEX2DEC(MID($N$26,3,5))*4+3,6)) -> 0x000023 | P26: - | Q26: X | R26: =CONCATENATE("0x",LEFT(DEC2HEX(HEX2DEC(MID(Module_Address_Usage!$C$18,3,8))+HEX2DEC(MID($N$26,3,5))*4+0,8),4),"_",RIGHT(DEC2HEX(HEX2DEC(MID(Module_Address_Usage!$C$18,3,8))+HEX2DEC(MID($N$26,3,5))*4+0,8),4)) -> 0x6000_0020
B27: X | O27: =CONCATENATE("0x",DEC2HEX(HEX2DEC(MID($N$26,3,5))*4+2,6)) -> 0x000022 | P27: - | Q27: X
B28: RW | H28: TX_RATE[3:0] | O28: =CONCATENATE("0x",DEC2HEX(HEX2DEC(MID($N$26,3,5))*4+1,6)) -> 0x000021 | P28: 0x00 | Q28: O
B29: RW | K29: SYNC_INS_MODE | O29: =CONCATENATE("0x",DEC2HEX(HEX2DEC(MID($N$26,3,5))*4+0,6)) -> 0x000020 | P29: 0x00 | Q29: O
A30: 0x00009 | B30: X | C30: TX_STATUS | L30: EMPTY: TX FIFO level = 0 HALF: TX FIFO level >= FIFO_DEPTH/2 FULL: TX FIFO level = FIFO_DEPTH | M30: 0b0: false 0b1: true (reset: EMPTY = 1) | N30: =CONCATENATE("0x",DEC2HEX(HEX2DEC(MID(Module_Address_Usage!$C$20,3,5))+HEX2DEC(MID($A30,3,5)),5)) -> 0x00009 | O30: =CONCATENATE("0x",DEC2HEX(HEX2DEC(MID($N$30,3,5))*4+3,6)) -> 0x000027 | P30: - | Q30: X | R30: =CONCATENATE("0x",LEFT(DEC2HEX(HEX2DEC(MID(Module_Address_Usage!$C$18,3,8))+HEX2DEC(MID($N$30,3,5))*4+0,8),4),"_",RIGHT(DEC2HEX(HEX2DEC(MID(Module_Address_Usage!$C$18,3,8))+HEX2DEC(MID($N$30,3,5))*4+0,8),4)) -> 0x6000_0024
B31: X | O31: =CONCATENATE("0x",DEC2HEX(HEX2DEC(MID($N$30,3,5))*4+2,6)) -> 0x000026 | P31: - | Q31: X
B32: X | O32: =CONCATENATE("0x",DEC2HEX(HEX2DEC(MID($N$30,3,5))*4+1,6)) -> 0x000025 | P32: - | Q32: X
B33: RO | I33: FULL | J33: HALF | K33: EMPTY | O33: =CONCATENATE("0x",DEC2HEX(HEX2DEC(MID($N$30,3,5))*4+0,6)) -> 0x000024 | P33: - | Q33: O
A34: 0x0000A ~ 0x0000B | B34: X | C34: Reserved | L34: Reserved | M34: Write ignored, read returns 0x0000_0000 | N34: =CONCATENATE("0x",DEC2HEX(HEX2DEC(MID(Module_Address_Usage!$C$20,3,5))+HEX2DEC(MID($A34,3,5)),5))&CHAR(10)&"~ "&CONCATENATE("0x",DEC2HEX(HEX2DEC(MID(Module_Address_Usage!$C$20,3,5))+HEX2DEC(MID($A34,13,5)),5)) -> 0x0000A ~ 0x0000B | O34: =CONCATENATE("0x",DEC2HEX(HEX2DEC(MID(CONCATENATE("0x",DEC2HEX(HEX2DEC(MID(Module_Address_Usage!$C$20,3,5))+HEX2DEC(MID($A34,3,5)),5)),3,5))*4+0,6))&CHAR(10)&"~ "&CONCATENATE("0x",DEC2HEX(HEX2DEC(MID(CONCATENATE("0x",DEC2HEX(HEX2DEC(MID(Module_Address_Usage!$C$20,3,5))+HEX2DEC(MID($A34,13,5)),5)),3,5))*4+3,6)) -> 0x000028 ~ 0x00002F | P34: - | Q34: X | R34: =CONCATENATE("0x",LEFT(DEC2HEX(HEX2DEC(MID(Module_Address_Usage!$C$18,3,8))+HEX2DEC(MID(CONCATENATE("0x",DEC2HEX(HEX2DEC(MID(Module_Address_Usage!$C$20,3,5))+HEX2DEC(MID($A34,3,5)),5)),3,5))*4+0,8),4),"_",RIGHT(DEC2HEX(HEX2DEC(MID(Module_Address_Usage!$C$18,3,8))+HEX2DEC(MID(CONCATENATE("0x",DEC2HEX(HEX2DEC(MID(Module_Address_Usage!$C$20,3,5))+HEX2DEC(MID($A34,3,5)),5)),3,5))*4+0,8),4))&CHAR(10)&"~ "&CONCATENATE("0x",LEFT(DEC2HEX(HEX2DEC(MID(Module_Address_Usage!$C$18,3,8))+HEX2DEC(MID(CONCATENATE("0x",DEC2HEX(HEX2DEC(MID(Module_Address_Usage!$C$20,3,5))+HEX2DEC(MID($A34,13,5)),5)),3,5))*4+3,8),4),"_",RIGHT(DEC2HEX(HEX2DEC(MID(Module_Address_Usage!$C$18,3,8))+HEX2DEC(MID(CONCATENATE("0x",DEC2HEX(HEX2DEC(MID(Module_Address_Usage!$C$20,3,5))+HEX2DEC(MID($A34,13,5)),5)),3,5))*4+3,8),4)) -> 0x6000_0028 ~ 0x6000_002F
A35: 0x0000C | B35: X | C35: TX_IRQ_ENABLE | L35: Interrupt enable of TX_IRQ_STATUS bits | M35: 0b0: disable 0b1: enable | N35: =CONCATENATE("0x",DEC2HEX(HEX2DEC(MID(Module_Address_Usage!$C$20,3,5))+HEX2DEC(MID($A35,3,5)),5)) -> 0x0000C | O35: =CONCATENATE("0x",DEC2HEX(HEX2DEC(MID($N$35,3,5))*4+3,6)) -> 0x000033 | P35: - | Q35: X | R35: =CONCATENATE("0x",LEFT(DEC2HEX(HEX2DEC(MID(Module_Address_Usage!$C$18,3,8))+HEX2DEC(MID($N$35,3,5))*4+0,8),4),"_",RIGHT(DEC2HEX(HEX2DEC(MID(Module_Address_Usage!$C$18,3,8))+HEX2DEC(MID($N$35,3,5))*4+0,8),4)) -> 0x6000_0030
B36: X | O36: =CONCATENATE("0x",DEC2HEX(HEX2DEC(MID($N$35,3,5))*4+2,6)) -> 0x000032 | P36: - | Q36: X
B37: X | O37: =CONCATENATE("0x",DEC2HEX(HEX2DEC(MID($N$35,3,5))*4+1,6)) -> 0x000031 | P37: - | Q37: X
B38: RW | H38: EN_UNDERRUN | I38: EN_FULL | J38: EN_LOW | K38: EN_EMPTY | O38: =CONCATENATE("0x",DEC2HEX(HEX2DEC(MID($N$35,3,5))*4+0,6)) -> 0x000030 | P38: 0x00 | Q38: O
A39: 0x0000D | B39: X | C39: TX_IRQ_STATUS | L39: ST_EMPTY: TX FIFO becomes empty ST_LOW: level falls below FIFO_DEPTH/2 ST_FULL: TX FIFO becomes full ST_UNDERRUN: FIFO empty at a word_tick | M39: Sticky, edge-triggered W1C: write 0b1 to clear | N39: =CONCATENATE("0x",DEC2HEX(HEX2DEC(MID(Module_Address_Usage!$C$20,3,5))+HEX2DEC(MID($A39,3,5)),5)) -> 0x0000D | O39: =CONCATENATE("0x",DEC2HEX(HEX2DEC(MID($N$39,3,5))*4+3,6)) -> 0x000037 | P39: - | Q39: X | R39: =CONCATENATE("0x",LEFT(DEC2HEX(HEX2DEC(MID(Module_Address_Usage!$C$18,3,8))+HEX2DEC(MID($N$39,3,5))*4+0,8),4),"_",RIGHT(DEC2HEX(HEX2DEC(MID(Module_Address_Usage!$C$18,3,8))+HEX2DEC(MID($N$39,3,5))*4+0,8),4)) -> 0x6000_0034
B40: X | O40: =CONCATENATE("0x",DEC2HEX(HEX2DEC(MID($N$39,3,5))*4+2,6)) -> 0x000036 | P40: - | Q40: X
B41: X | O41: =CONCATENATE("0x",DEC2HEX(HEX2DEC(MID($N$39,3,5))*4+1,6)) -> 0x000035 | P41: - | Q41: X
B42: RW | H42: ST_UNDERRUN | I42: ST_FULL | J42: ST_LOW | K42: ST_EMPTY | O42: =CONCATENATE("0x",DEC2HEX(HEX2DEC(MID($N$39,3,5))*4+0,6)) -> 0x000034 | P42: 0x00 | Q42: O
A43: 0x0000E | B43: X | C43: TX_FIFO_CLEAR | L43: CLR: flush the TX FIFO only | M43: Write 0b1: flush | N43: =CONCATENATE("0x",DEC2HEX(HEX2DEC(MID(Module_Address_Usage!$C$20,3,5))+HEX2DEC(MID($A43,3,5)),5)) -> 0x0000E | O43: =CONCATENATE("0x",DEC2HEX(HEX2DEC(MID($N$43,3,5))*4+3,6)) -> 0x00003B | P43: - | Q43: X | R43: =CONCATENATE("0x",LEFT(DEC2HEX(HEX2DEC(MID(Module_Address_Usage!$C$18,3,8))+HEX2DEC(MID($N$43,3,5))*4+0,8),4),"_",RIGHT(DEC2HEX(HEX2DEC(MID(Module_Address_Usage!$C$18,3,8))+HEX2DEC(MID($N$43,3,5))*4+0,8),4)) -> 0x6000_0038
...
